Workbook

Sheet Overview
A1: Honoured — Native iOS Progress Tracker (V1.1 + V1.2)
A2: Progress, task status and open questions for the native iOS app and the web and database work it depends on. Last updated Oct 11; every status was checked against the code, the published web app and the live database.
A3: Scope: the iOS app, plus the Lovable web app and Supabase changes each milestone needs. Android is out of scope (one Android fix is listed under extra work).
A5: WHERE THINGS STAND — Oct 11
A6: • V1.2 M1 (Settings, UI polish, Health source): built and live in the web app. Left: what the Health source choice does on a day without data (Open Items #17, #18) and checks on a real iPhone.
A7: • V1.2 M2 (Icon, formerly The Oath): built and live. A real iPhone has received server-started Icon cards since Oct 6, with the full cycle (morning card, HONOURED, renewal, close) on Oct 9. Left: the real-iPhone acceptance pass (evening card, fallback notification, sign-out) and push setup for the client's App ID.
A8: • V1.2 M3 (Word Tracker): built and live. The web app was published on Oct 10 and 11, the database holds the word scoring with the 24-hour starting-count window and the 30-minute sync grace window, and the iPhone code is on main. Checked end to end on the simulator against the live web app and database: all five formats, rename, move, delete and reconnect, reminders, and a read just after midnight that counted for the day before. Left: an iPhone build and the real-iPhone checks, starting with a Scrivener project from Dropbox (Gate A).
A9: • V1.2 M4 (Multi-Activity Calendar): built and live (published Oct 11). Each calendar day shows one band per result, and a tap opens a sheet with every result of the day, its time, and that day's journal notes and Voice of Change recordings. Checked on the simulator; a real-iPhone pass is left.
A10: • V1.1: built, with the web side live and test builds on real iPhones (including the client's) under a test App ID. Not yet on TestFlight for the client or submitted to the App Store; that needs the publishing account and final App ID (Open Item #14).
A11: • Needs attention: the client's iPhone has not uploaded general Health data since Oct 2. Cause found on Oct 11: an upload batch too large for the server stays stuck at the head of the phone's queue. Fixed in the app; it takes effect with the next iPhone build (Open Item #20).
A13: V1.2 MILESTONES
A14: Milestone | B14: Dates | C14: Payment | D14: Est. hours | E14: Actual hours | F14: % complete | G14: Deliverable
A15: M1 | B15: Oct 1 – 3 | D15: =SUMIF('V1.2 Tasks'!B:B,"V1.2 M1",'V1.2 Tasks'!F:F) -> 26 | E15: =SUMIF('V1.2 Tasks'!B:B,"V1.2 M1",'V1.2 Tasks'!G:G) -> 0 | F15: =IF(COUNTIF('V1.2 Tasks'!B:B,"V1.2 M1")=0,0,COUNTIFS('V1.2 Tasks'!B:B,"V1.2 M1",'V1.2 Tasks'!H:H,"Done")/COUNTIF('V1.2 Tasks'!B:B,"V1.2 M1")) -> 0.66666667 | G15: Settings handoff, collapsible Settings, smooth signature, pull-to-refresh, Health source choice (Apple Watch first)
A16: M2 | B16: Oct 1 – 9 | D16: =SUMIF('V1.2 Tasks'!B:B,"V1.2 M2",'V1.2 Tasks'!F:F) -> 64 | E16: =SUMIF('V1.2 Tasks'!B:B,"V1.2 M2",'V1.2 Tasks'!G:G) -> 0 | F16: =IF(COUNTIF('V1.2 Tasks'!B:B,"V1.2 M2")=0,0,COUNTIFS('V1.2 Tasks'!B:B,"V1.2 M2",'V1.2 Tasks'!H:H,"Done")/COUNTIF('V1.2 Tasks'!B:B,"V1.2 M2")) -> 0.92307692 | G16: Icon (The Oath): Icon sheet and signing, daily results from Health, server-pushed Live Activity card, recap
A17: M3 | B17: Oct 9 – 11 | D17: =SUMIF('V1.2 Tasks'!B:B,"V1.2 M3",'V1.2 Tasks'!F:F) -> 36 | E17: =SUMIF('V1.2 Tasks'!B:B,"V1.2 M3",'V1.2 Tasks'!G:G) -> 0 | F17: =IF(COUNTIF('V1.2 Tasks'!B:B,"V1.2 M3")=0,0,COUNTIFS('V1.2 Tasks'!B:B,"V1.2 M3",'V1.2 Tasks'!H:H,"Done")/COUNTIF('V1.2 Tasks'!B:B,"V1.2 M3")) -> 0.71428571 | G17: Basic Word Tracker: Word, TextEdit and Scrivener counts read on the iPhone, scored as Icon days
A18: M4 | B18: Oct 11 | D18: =SUMIF('V1.2 Tasks'!B:B,"V1.2 M4",'V1.2 Tasks'!F:F) -> 27 | E18: =SUMIF('V1.2 Tasks'!B:B,"V1.2 M4",'V1.2 Tasks'!G:G) -> 0 | F18: =IF(COUNTIF('V1.2 Tasks'!B:B,"V1.2 M4")=0,0,COUNTIFS('V1.2 Tasks'!B:B,"V1.2 M4",'V1.2 Tasks'!H:H,"Done")/COUNTIF('V1.2 Tasks'!B:B,"V1.2 M4")) -> 0.75 | G18: Multi-Activity Calendar: a band per result and a full day sheet
A19: Total | D19: =SUM(D15:D18) -> 153 | E19: =SUM(E15:E18) -> 0 | F19: =IF(SUMPRODUCT(COUNTIF('V1.2 Tasks'!B:B,{"V1.2 M1","V1.2 M2","V1.2 M3","V1.2 M4"}))=0,0,SUMPRODUCT(COUNTIFS('V1.2 Tasks'!B:B,{"V1.2 M1","V1.2 M2","V1.2 M3","V1.2 M4"},'V1.2 Tasks'!H:H,"Done"))/SUMPRODUCT(COUNTIF('V1.2 Tasks'!B:B,{"V1.2 M1","V1.2 M2","V1.2 M3","V1.2 M4"}))) -> 0.8
A21: V1.2 TASKS BY STATUS
A22: Status | B22: Tasks | C22: Est. hours
A23: Done | B23: =COUNTIFS('V1.2 Tasks'!H:H,"Done",'V1.2 Tasks'!B:B,"V1.2 M*") -> 24 | C23: =SUMIFS('V1.2 Tasks'!F:F,'V1.2 Tasks'!H:H,"Done",'V1.2 Tasks'!B:B,"V1.2 M*") -> 119
A24: In progress | B24: =COUNTIFS('V1.2 Tasks'!H:H,"In progress",'V1.2 Tasks'!B:B,"V1.2 M*") -> 6 | C24: =SUMIFS('V1.2 Tasks'!F:F,'V1.2 Tasks'!H:H,"In progress",'V1.2 Tasks'!B:B,"V1.2 M*") -> 34
A25: Not started | B25: =COUNTIFS('V1.2 Tasks'!H:H,"Not started",'V1.2 Tasks'!B:B,"V1.2 M*") -> 0 | C25: =SUMIFS('V1.2 Tasks'!F:F,'V1.2 Tasks'!H:H,"Not started",'V1.2 Tasks'!B:B,"V1.2 M*") -> 0
A26: Blocked | B26: =COUNTIFS('V1.2 Tasks'!H:H,"Blocked",'V1.2 Tasks'!B:B,"V1.2 M*") -> 0 | C26: =SUMIFS('V1.2 Tasks'!F:F,'V1.2 Tasks'!H:H,"Blocked",'V1.2 Tasks'!B:B,"V1.2 M*") -> 0
A27: Deferred | B27: =COUNTIFS('V1.2 Tasks'!H:H,"Deferred",'V1.2 Tasks'!B:B,"V1.2 M*") -> 0 | C27: =SUMIFS('V1.2 Tasks'!F:F,'V1.2 Tasks'!H:H,"Deferred",'V1.2 Tasks'!B:B,"V1.2 M*") -> 0
A29: NEXT STEPS
A30: • Ship an iPhone build from main: Word Tracker, sync grace window, password saving (X-07) and native session refresh (X-12).
A31: • Run the Word Tracker device checks (docs/phase2/M3-device-test-plan.vi.md): a Scrivener project from Dropbox first (Gate A), then the acceptance cases (Gate D).
A32: • Install the next iPhone build on the client's iPhone and confirm its queued Health data arrives (Open Item #20).
A33: • Run the real-iPhone acceptance passes for M1 (Apple Watch and Garmin source), M2 (evening card, fallback notification, sign-out) and M4 (calendar bands, day sheet, VoiceOver).
A34: • Client: publishing account, final App ID and APNs key (#14), Google client IDs (#15), the decisions in Open Items #16–#18, #21, #23–#25 and #28, and a review of the two Word Tracker documents (#27).
A35: • Then TestFlight for the client and App Store submission (N-21, N-22).
A37: V1.1 MILESTONES
A38: Milestone | B38: Dates | C38: Payment | D38: Est. hours | E38: Actual hours | F38: % complete | G38: Deliverable
A39: M1 | B39: Sep 8 | C39: $500 | D39: =SUMIF('V1.1 Tasks'!B:B,"M1",'V1.1 Tasks'!F:F) -> 8 | E39: =SUMIF('V1.1 Tasks'!B:B,"M1",'V1.1 Tasks'!G:G) -> 0 | F39: =IF(COUNTIF('V1.1 Tasks'!B:B,"M1")=0,0,COUNTIFS('V1.1 Tasks'!B:B,"M1",'V1.1 Tasks'!H:H,"Done")/COUNTIF('V1.1 Tasks'!B:B,"M1")) -> 1 | G39: Scope locked: bridge contract, database schema, project configuration
A40: M2 | B40: Sep 8 – 28 | C40: $700 | D40: =SUMIF('V1.1 Tasks'!B:B,"M2",'V1.1 Tasks'!F:F) -> 135 | E40: =SUMIF('V1.1 Tasks'!B:B,"M2",'V1.1 Tasks'!G:G) -> 0 | F40: =IF(COUNTIF('V1.1 Tasks'!B:B,"M2")=0,0,COUNTIFS('V1.1 Tasks'!B:B,"M2",'V1.1 Tasks'!H:H,"Done")/COUNTIF('V1.1 Tasks'!B:B,"M2")) -> 0.72727273 | G40: V1.1 on the App Store — HealthKit, notifications, timer, gong, Sign in with Apple
A41: M3 | B41: Sep 29 – Oct 12 | C41: $500 | D41: =SUMIF('V1.1 Tasks'!B:B,"M3",'V1.1 Tasks'!F:F) -> 40 | E41: =SUMIF('V1.1 Tasks'!B:B,"M3",'V1.1 Tasks'!G:G) -> 0 | F41: =IF(COUNTIF('V1.1 Tasks'!B:B,"M3")=0,0,COUNTIFS('V1.1 Tasks'!B:B,"M3",'V1.1 Tasks'!H:H,"Done")/COUNTIF('V1.1 Tasks'!B:B,"M3")) -> 0.57142857 | G41: Dynamic Island (Live Activity) and Google Sign-In shipped
A42: Total | C42: $1,700 | D42: =SUM(D39:D41) -> 183 | E42: =SUM(E39:E41) -> 0 | F42: =IF(SUMPRODUCT(COUNTIF('V1.1 Tasks'!B:B,{"M1","M2","M3"}))=0,0,SUMPRODUCT(COUNTIFS('V1.1 Tasks'!B:B,{"M1","M2","M3"},'V1.1 Tasks'!H:H,"Done"))/SUMPRODUCT(COUNTIF('V1.1 Tasks'!B:B,{"M1","M2","M3"}))) -> 0.72727273
A44: CONFIRMED DECISIONS
A45: Topic | B45: Decision
A46: V1.2 · Icon | B46: The Oath ships as 'Icon' (client rename, Oct 1). The Apple Wallet pass was replaced by a Live Activity card (scope v6, Sep 28).
...

Sheet Weekly Progress
A1: Weekly Progress
A2: Week-level summary, updated as work lands. Est. h covers both V1.1 and V1.2 tasks planned for the week. Screenshots and build links go in the Screenshots sheet.
A4: Week | B4: Dates | C4: Focus | D4: Planned this week | E4: Status | F4: Est. h | G4: Actual h | H4: Delivered so far | I4: Blockers | J4: Notes for client
A5: Scope lock | B5: Sep 8 | C5: Contract and schema locked | D5: Bridge v2 message contract, Supabase schema and RLS, project configuration, written confirmation of decisions | E5: Done | F5: =SUMIF('V1.1 Tasks'!C:C,"Scope lock",'V1.1 Tasks'!F:F)+SUMIF('V1.2 Tasks'!C:C,"Scope lock",'V1.2 Tasks'!F:F) -> 8 | H5: Bridge v2 contract, metric mapping and client decisions confirmed. Schema design done; apply path pending.
A6: Week 1 | B6: Sep 8 – 14 | C6: HealthKit foundation | D6: Permission flow, reads for all seven metrics, Supabase sync, offline queue, duplicate protection | E6: Done | F6: =SUMIF('V1.1 Tasks'!C:C,"Week 1",'V1.1 Tasks'!F:F)+SUMIF('V1.2 Tasks'!C:C,"Week 1",'V1.2 Tasks'!F:F) -> 45 | H6: Native Week 1 code completed and audited: HealthKit permission/anchored reads, source-deduplicated daily totals, Supabase sync, user-bound offline queue, real reconnect retry, Keychain token refresh and bridge v2. Supabase production schema/RPC access controls rechecked; Lovable commit 9c13 passed 91 web tests. | I6: Real-device HealthKit checks (permission sheet decisions, second-run anchors, deletion, airplane mode) are scheduled as Week 3 QA and need Apple Developer access. Production E2E still needs Lovable to publish. | J6: Sep 15 audit fixed reconnect reads, retry looping, account isolation, finite-number validation, overlapping sleep totals and late historical samples. Static checks pass. The attempted simulator build was stopped with no result; latest confirmed simulator build remains Sep 14.
A7: Week 2 | B7: Sep 15 – 21 | C7: Ceremony and identity | D7: Background sync, Testament Timer notifications, goal-completion alerts, gong sound, Sign in with Apple | E7: Done | F7: =SUMIF('V1.1 Tasks'!C:C,"Week 2",'V1.1 Tasks'!F:F)+SUMIF('V1.2 Tasks'!C:C,"Week 2",'V1.2 Tasks'!F:F) -> 50 | H7: N-09 to N-16 delivered. Sep 25 update: HealthKit background delivery now requests immediate observer callbacks for all nine metrics and refreshes Live Activities before the full sync pass. Notification permission can be enabled from the in-app Settings row. Completion sound defaults on and uses a bundled three-strike gong. Lovable notification settings are published. | I7: Real-device acceptance remains for background timing, lock-screen sound under device Focus/silent settings, notification taps and HealthKit delivery. iOS schedules HealthKit background launches opportunistically, even with immediate frequency. | J7: Native commit 12c0270; 94/94 iOS tests passed. Lovable notification settings published from commits 43173dad and 0075b4b; 295 web tests passed before the Flash guidance follow-up.
A8: Week 3 | B8: Sep 22 – 28 | C8: QA and release | D8: Permission and background QA, bug fixes, privacy paperwork, TestFlight, App Store submission | E8: In progress | F8: =SUMIF('V1.1 Tasks'!C:C,"Week 3",'V1.1 Tasks'!F:F)+SUMIF('V1.2 Tasks'!C:C,"Week 3",'V1.2 Tasks'!F:F) -> 40 | H8: Device testing moved to real iPhones, including the client's own from Sep 23: Health data synced and Sign in with Apple worked end to end, and a Live Activity device test led to the completion pulse (59055e8). Fixes from testing: timer reporting under Focus (5b84381) and the completion sound cutting into music (b33c764). The Dynamic Island work (N-23 to N-27) and Google Sign-In for iPhone and Android landed early (08fd447, Sep 24); notification settings and Flash guidance were published Sep 25; Health units refined Sep 27; version 1.0.4 (build 1) on Sep 28. | I8: No App Store submission: the release needs the publishing account and final App ID, as every build uses the test App ID. Privacy label and HealthKit review notes not written. The QA matrix (N-17/N-18) has not been run as a recorded pass. | J8: The App Store submission planned for Sep 28 has not happened yet. Testing moved to real iPhones on a test App ID, and the issues found were fixed the same week.
A9: Week 4 | B9: Sep 29 – Oct 5 | C9: Dynamic Island build | D9: Widget Extension target, Live Activity presentations, activity lifecycle | E9: In progress | F9: =SUMIF('V1.1 Tasks'!C:C,"Week 4",'V1.1 Tasks'!F:F)+SUMIF('V1.2 Tasks'!C:C,"Week 4",'V1.2 Tasks'!F:F) -> 103.5 | H9: V1.1: Sign in with Apple adds Apple to the signed-in account (Oct 1); Terms, Privacy Policy and sign-up consent (Oct 4); Android link crash fixed (Oct 4); version 1.0.5 (build 1) on Oct 3. V1.2 M1 built and published: Settings handoff, collapsible Settings, smooth signature, pull-to-refresh and the Health source choice. V1.2 M2 built: Icon sheet and signing, Icon database, scoring, push tokens, the every-minute push job, the Icon card, affirmations and recap (both approved Oct 4), and History entries per Icon day (Oct 5). | I9: Release still waits on the publishing account and App ID; Google sign-in inside the iPhone app waits on its client IDs. | J9: Most of the week went to V1.2 M1 and M2 (see the V1.2 Tasks sheet). The Lock Screen and expanded Live Activity views still need a recorded device pass (N-24).
A10: Week 5 | B10: Oct 6 – 12 | C10: Dynamic Island finish + Google | D10: Flash-for-alerts guidance, HealthKit goal hook, Google Sign-In, QA and update submission | E10: In progress | F10: =SUMIF('V1.1 Tasks'!C:C,"Week 5",'V1.1 Tasks'!F:F)+SUMIF('V1.2 Tasks'!C:C,"Week 5",'V1.2 Tasks'!F:F) -> 51.5 | H10: Published web build 48b7a74 (Oct 7) carries every V1.1 web part and V1.2 M1 and M2. Icon card renewal before iOS's 8-hour limit and the Testament Timer for Icons (Oct 6); the client's Icon screen changes (Oct 6–7). A real iPhone has received server-started Icon cards since Oct 6, with a full cycle on Oct 9. The V1.2 M3 Word Tracker was built in code and tested on Oct 9–10 (iPhone 188/188, web 573/573, database 63/63); it is not live yet. Oct 10: the Word Tracker database change was applied to production; the review gaps were fixed (reads from any screen, combining marks, cut-off reminders, Scrivener in the file picker); the web part is built (not yet published) and the iPhone part is committed on a branch. Oct 10–11: the Word Tracker went live (web published, three database changes, iPhone code on main) and passed end to end on the simulator, including the grace window across midnight; M4 (calendar bands and the day sheet) was built and published. | I10: Publishing account and final App ID; Google client IDs for the iPhone app; the Word Tracker web publish and iPhone build. The stalled Health upload (since Oct 2 on the client's iPhone) was traced and fixed in the app on Oct 11; it needs the next iPhone build. | J10: Next: an iPhone build, the real-iPhone acceptance passes (Word Tracker first, then M1, M2 and M4) and the Health upload investigation.
A11: Week 6 | B11: Oct 13 – 19 | C11: iPhone build and device acceptance | D11: Ship an iPhone build from main; Word Tracker device checks (Gate A first, then Gate D); real-iPhone passes for M1, M2 and M4; Health upload investigation; client decisions (Open Items #14–#18, #21, #23–#25, #27, #28) | E11: Not started | F11: =SUMIF('V1.1 Tasks'!C:C,"Week 6",'V1.1 Tasks'!F:F)+SUMIF('V1.2 Tasks'!C:C,"Week 6",'V1.2 Tasks'!F:F) -> 38 | I11: The client's publishing account and App ID

Sheet V1.2 Tasks
A1: V1.2 Task Tracker
A2: Every V1.2 task (M1–M4), plus extra work done along the way (X rows, not in the estimate). Statuses were checked on Oct 10 against the code, the published web app and the live database.
A4: ID | B4: Milestone | C4: Week | D4: Task | E4: Layer | F4: Est. h | G4: Actual h | H4: Status | I4: Done when | J4: Evidence | K4: Notes
A5: M1-01 | B5: V1.2 M1 | C5: Week 4 | D5: Settings handoff: notification toggle works, placeholder text removed, confirmation before reset | E5: Web | F5: 3 | H5: Done | I5: Toggle works end to end, no placeholder copy, reset asks first | J5: Lovable be542a6 + 5cb9811 (Oct 1): notification-toggle.ts, reset-confirmation.ts, Settings.tsx · tests/settings-handoff.test.ts (18) · in the published web build 48b7a74 | K5: Notifications in Settings is now a real switch: it asks for permission the first time, then opens iPhone Settings, because iOS requires the change to be made there. The 'Coming soon' download rows are gone and Reset everything always asks before erasing. Live in the web app; not yet tried on a real iPhone.
A6: M1-02 | B6: V1.2 M1 | C6: Week 4 | D6: Settings as collapsible (accordion) sections | E6: Web | F6: 3 | H6: Done | I6: Every Settings section opens/closes | J6: Lovable e05c527 (Oct 1) and 00ca8f2 (Oct 2: every section starts closed) · settings-accordion.ts · tests/m1-06.test.ts · in the published web build 48b7a74 | K6: Each Settings section opens and closes from its heading. Following the Oct 2 feedback, every section starts closed, so Settings opens as a short list of headings. Not yet tried on a real iPhone (including VoiceOver).
A7: M1-03 | B7: V1.2 M1 | C7: Week 4 | D7: Smooth signature strokes (Bézier curves) | E7: Web | F7: 3 | H7: Done | I7: Signature pad draws smooth curves on iPhone | J7: Lovable e05c527 (Oct 1): signature-path.ts (quadratic Bézier curves, jitter filter), SignatureCanvas.tsx with coalesced pointer events · 7 tests · the landscape pad reuses it · in the published web build 48b7a74 | K7: Signatures are drawn as smooth curves instead of short straight lines, and tiny hand tremors are ignored. The landscape signing pad uses the same drawing. The feel on a real iPhone still needs a quick check.
A8: M1-04 | B8: V1.2 M1 | C8: Week 4 | D8: Pull-to-refresh on Home, History and Contract | E8: Web | F8: 3.5 | H8: Done | I8: Pull refreshes data on all three screens without losing form input | J8: Lovable e05c527 (Oct 1): PullToRefresh.tsx, pull-to-refresh.ts, screen-refresh.ts on Home, History and Contract · 8 tests · in the published web build 48b7a74 | K8: Pulling down at the top of Home, History or Contract reloads the latest data, and each screen also has a small Refresh button. On Contract the pull switches off once you start filling in the form, so a draft is never lost. Not yet tried on a real iPhone.
A9: M1-05 | B9: V1.2 M1 | C9: Week 4 | D9: HealthKit source choice with Apple Watch preferred, plus fallback | E9: Native + Web | F9: 8.5 | H9: In progress | I9: Source chosen in Settings; Watch preferred; sensible fallback when the source has no data | J9: Native c825a76 (Oct 3): HealthSourcePreference.swift (Apple Watch, then iPhone, then other watches), source filter in HealthKitService.swift, GET_HEALTH_SOURCES / SET_HEALTH_SOURCE_PREFERENCE, 7 tests · web ffe239b (Oct 1): Settings › Health source picker and Home source label, 12 tests, published in 48b7a74 · gaps: no fallback on a day the chosen source recorded nothing; a Watch no longer worn stays the automatic choice; a Garmin ranks below the iPhone; no 'accuracy may vary' note | K9: Settings › Health now has a 'Steps & distance source' choice. 'Let Honoured decide' uses the Apple Watch first, then the iPhone, and Home shows which source is in use. Still open: what to count on a day the chosen source recorded nothing (for example, the Watch was not worn), whether a Garmin should come before the iPhone, and the 'accuracy may vary' note for iPhone-only users (Open Items #17, #18).
A10: M1-06 | B10: V1.2 M1 | C10: Week 4 | D10: Test and bug fixes | E10: QA | F10: 5 | H10: In progress | I10: No known blocker defects; device check of the source choice | J10: Web suites passed at every step (573/573 at Lovable 774afec) · native 173 committed tests pass (188/188 with the Word Tracker, Oct 10) · fixes filed under M1: Apple account preservation (Lovable e6e07b5) and sign-in restore after a cold start (c825a76) · no real-iPhone check recorded; no Apple Watch data has reached Honoured yet | K10: Automated tests pass for the web app and the iPhone app, and two sign-in fixes were made along the way. Still to do: a check on a real iPhone with an Apple Watch (and with a Garmin), and finding out why general Health data stopped reaching the server on Oct 7 (Open Item #20).
A11: M2-01 | B11: V1.2 M2 | C11: Week 4 | D11: Icon row on Contract (unset/set), status pill, Standing Contract retired (existing ones run to expiry) | E11: Web | F11: 4 | H11: Done | I11: The Icon row and ICON · UNSIGNED pill show on Contract, Standing Contract is no longer offered and existing Standing contracts keep running | J11: Lovable 38b9a0a, be9e867, 4b88e38 (Oct 1, renamed to Icon), 86362c3 + 8e6ac11 (Oct 5–6, Icon symbol), 1aa3e69 (Oct 7, badges) · IconRow.tsx, icon.ts · tests/icon.test.ts · in the published web build 48b7a74 | K11: Live: the Contract page has the Icon row ('Become an Icon (for multi-day goals)', then a gold days and period summary) and the ICON · UNSIGNED pill, and Standing Contract is no longer offered. The Oath was renamed Icon at the client's request (Oct 1); the symbol and badge sizes follow the Oct 5–7 requests. A signed daily contract still shows the old 'Standing Contract' heading (Open Item #21).
A12: M2-02 | B12: V1.2 M2 | C12: Week 4 | D12: Icon sheet: 7-day picker, duration quick picks + custom (2 days–1 year), morning/evening reminders, live session count, Remove, swipe to dismiss | E12: Web | F12: 7.5 | H12: Done | I12: The sheet sets days, period and reminders, always shows the session count, and Remove, Cancel and swipe down behave | J12: Lovable 4b88e38 and 6018a22 (Oct 1), 670c452 (reminder rule): IconSheet in IconRow.tsx, countSessions / periodEnd / validateCustomDays in icon.ts · Icon tests · in the published web build 48b7a74 | K12: The Icon sheet is complete and published: seven day buttons, 1 Week to 1 Year quick picks (1 Month by default) or a custom 2-day to 1-year length, morning and evening reminders, and the always-visible 'You are committing to N sessions' count. Remove Icon clears it; Cancel, a tap outside or a swipe down on the grab handle close it. The swipe starts only on the small grab handle, so its feel on a real iPhone, and VoiceOver, are checked in M2-13.
A13: M2-03 | B13: V1.2 M2 | C13: Week 4 | D13: Per-day deadline, terms locked after signing, early exit = AMENDED, list of running Icons | E13: Web + Supabase | F13: 4 | H13: Done | I13: Deadline is a daily cut-off, terms lock at signing, End early marks the remaining sessions AMENDED, running Icons are listed | J13: Lovable 310b3d7 (Oct 1), cfe2edf (Oct 2, 00:00 cut-off), c6cad1a + 0141863 (Oct 4, one Icon per day), 1aa3e69 (Oct 7) · production triggers contracts_icon_guard / contracts_icon_days / contracts_icon_reserve · no AMENDED day in production yet | K13: With an Icon set, Deadline becomes a daily cut-off time (00:00 means the end of each Icon day). After signing, the database keeps days, period and target locked, 'End early' marks the remaining sessions AMENDED, and running Icons are listed on the Contract tab and on Home. At the client's request a day held by an Icon accepts no other contract (Oct 4), and Home no longer offers 'Sign a contract' while one is in force (Oct 7).
A14: M2-04 | B14: V1.2 M2 | C14: Week 4 | D14: Supabase: Icon schedule, daily results, reminder times, timezone, RLS, web sync | E14: Supabase | F14: 4.5 | H14: Done | I14: Production stores each Icon's terms, time zone and reminders, one result row per scheduled day, each person reads only their own data, and the web syncs both | J14: Production (checked Oct 10): icon_* columns on contracts, icon_days, Icon triggers and icon_schedule(), row-level security (own rows only; results written by the server) · web sync in contract-sync.ts and icon-days.ts (Lovable 310b3d7, 94615a0) · applied directly on Oct 1; the setup script is not saved in a repository | K14: The Icon database is live: each Icon contract stores its days, period, daily cut-off, time zone, reminder times and Health target, and every scheduled day has its own result row. Each person can read only their own Icon data, and results are written only by the server. The setup script still needs saving with the project files (Open Item #22).
A15: M2-05 | B15: V1.2 M2 | C15: Week 4 | D15: Scoring: HONOURED once synced Health data meets the target, BROKEN after the deadline from full-day data, pending > 24 h → BROKEN, no-permission handling | E15: Supabase + iOS | F15: 8 | H15: Done | I15: HONOURED as soon as the target is met, BROKEN from a full-day reading, BROKEN (no data) 24 h after the cut-off; a declined permission never scores as zero | J15: Native c825a76 (Oct 3): IconVerifier.swift, IconMeasurement.swift (8 tests) · production: record_icon_measurements(), expire_icon_days(), cron icon-days-expire every 15 min (875 runs, none failed) · real Icon days already stamped HONOURED and BROKEN from Health readings | K15: Live in production. A measured Icon day is stamped HONOURED as soon as the target is met, BROKEN once the full day has been read after the cut-off, and BROKEN (no data) 24 hours after the cut-off if nothing was reported, so a missing Health permission never counts as zero. HONOURED and BROKEN from Health readings have already happened on real days.
A16: M2-06 | B16: V1.2 M2 | C16: Week 4 | D16: Push infrastructure: capability, device + push-to-start token registration via the bridge, stored per account, removed on sign-out | E16: iOS + Supabase | F16: 5 | H16: Done | I16: The app registers its device, push-to-start and card tokens for the signed-in account, and sign-out or an account switch removes them | J16: Native 9fd8622 (Oct 4): PushTokenRegistry.swift, PushTokenSupport.swift (6 tests), aps-environment entitlement · production: register_push_token / unregister_push_tokens, push_tokens with row-level security · one real iPhone registered since Oct 6 | K16: The app registers its notification, push-to-start and card tokens for the signed-in account and removes them when the person signs out or switches account. A real iPhone has been registered since Oct 6. Removal on sign-out still needs a check on the phone (M2-13).
... A34: M4-04 | B34: V1.2 M4 | C34: Week 6 | D34: Test and bug fixes | E34: QA | F34: 6 | H34: In progress | I34: Calendar and day sheet behave correctly with no, one and several results per day; no known blocker defects | J34: Web tests 622/622 in four time zones (tests/history-calendar.test.ts, history-entries.test.ts) · simulator pass on Oct 11; one wording fix (0371495) · not done: a real iPhone (legibility, swipe, VoiceOver, a busy month) | K34: Automated tests and the simulator pass, and the one issue found was fixed. A real-iPhone pass is left.
A35: X-01 | B35: Extra | C35: Week 3 | D35: Completion sound no longer interrupts other audio | E35: Native | H35: Done | I35: The gong never cuts into music or podcasts | J35: Native b33c764 (Sep 25): NotificationSound.swift, HonouredAppDelegate.swift, HonouredWebView.swift | K35: The completion sound is left out when other audio is already playing, and the audio session is released in the background. The app shell now defaults the sound to off, but the published web app still starts it on (Open Item #16).
A36: X-02 | B36: Extra | C36: Week 3 | D36: Health display and target units | E36: Web | H36: Done | I36: Steps can be committed in km or miles; labels updated | J36: Lovable 0abbd4f and 9076bf5 (Sep 27) · tests/health-goals.test.ts, target-units.test.ts · in the published web build 48b7a74 | K36: Steps can now be committed in km or miles (checked against walking and running distance), Running and Rucking accept step targets, and the step limit is 50,000. The Home card now reads 'Distance'.
A37: X-03 | B37: Extra | C37: Week 3 | D37: V1.2 scope, clarifications and estimate | E37: Docs | H37: Done | I37: Milestones, estimate and client decisions written down | J37: Native repo 42c0d8b and 82e808e (Sep 28): docs/phase2 milestones, estimate and the M2–M3 re-estimate with the Sep 28 decisions | K37: Scope, clarification questions and hour estimates for the four V1.2 milestones were prepared and finalised with the client's Sep 28 decisions.
A38: X-04 | B38: Extra | C38: Week 4 | D38: Sign in with Apple keeps the account you are signed in to | E38: Web | H38: Done | I38: Apple is added to the signed-in account; a different Apple ID is refused | J38: Lovable e6e07b5 + fcb2a30 (Oct 1): apple-auth.ts, tests/apple-sign-in.test.ts · in the published web build 48b7a74 | K38: If someone who is already signed in taps Sign in with Apple, Apple is added to that same account instead of switching to another one, so no data is left behind. A different Apple ID is refused with a clear message. Not yet checked on a real device.
A39: X-05 | B39: Extra | C39: Week 4 | D39: Landscape signing on the Contract screen | E39: Native + Web | H39: Done | I39: The Contract screen can rotate so the signature has a wider pad | J39: Lovable 5c7abde (Oct 1) · native c825a76 (Oct 3): OrientationLock.swift, SET_LANDSCAPE_ALLOWED / ORIENTATION_STATE in docs/phase1/bridge.md | K39: On iPhone the Contract screen can rotate to landscape so the signature can be drawn on a wider pad; the rest of the app stays portrait. Not yet checked on a real device.
A40: X-06 | B40: Extra | C40: Week 4 | D40: Show/hide password button | E40: Web | H40: Done | I40: The sign-in form can show or hide the password | J40: Lovable f386bc2 (Oct 3): Auth.tsx · in the published web build 48b7a74 | K40: The sign-in form has an eye button to show or hide the password while typing.
A41: X-07 | B41: Extra | C41: Week 5 | D41: Save login to iPhone Passwords (iCloud Keychain) | E41: Native + Web | H41: In progress | I41: After sign-in or sign-up the iPhone offers to save the login to Passwords | J41: Web: Lovable 768dd27 (Oct 3), 203c1ef (Oct 4), 48b7a74 (Oct 7) · native: 2d925b7 on main since Oct 10 (SAVE_WEB_CREDENTIAL, webcredentials associated domain) · the apple-app-site-association file lists only the test App ID · no device check yet | K41: Both sides are built: the web page asks the iPhone to save the login and the app shows the system prompt. Left: a device check, and the final App ID in the web app's association file before release.
A42: X-08 | B42: Extra | C42: Week 4 | D42: Terms of Use, Privacy Policy and sign-up consent | E42: Web | H42: Done | I42: Legal pages are live and sign-up asks for consent | J42: Lovable ad6d676, ae4b6a3, 85bdf31 (Oct 4), 203c1ef · /privacy and /terms return 200 · in the published web build 48b7a74 | K42: Terms of Use and Privacy Policy pages were added and open as in-app sheets, and signing in or creating an account asks for consent. The public Privacy Policy page can serve as the policy URL for the App Store listing (N-20).
A43: X-09 | B43: Extra | C43: Week 4 | D43: Android app no longer closes on links it cannot open | E43: Native (Android) | H43: Done | I43: A link no installed app can open is ignored instead of crashing | J43: Native 5a1dd1e (Oct 4): MainActivity.kt | K43: Fixed a crash in the Android app: a link that no installed app can open is now ignored instead of closing Honoured.
A44: X-10 | B44: Extra | C44: Week 4 | D44: History calendar shows each Icon day | E44: Web | H44: Done | I44: History lists each Icon day on its own date with what decided it | J44: Lovable 499d0dd (Oct 5): history-entries.ts, History.tsx, tests/history-entries.test.ts · in the published web build 48b7a74 | K44: At the client's request, History lists each Icon day on its own date with 'Session x of y' and what decided it (Health reading, self-report or no data). An Icon ended early adds one AMENDED entry.
A45: X-11 | B45: Extra | C45: Week 5 | D45: Testament Timer for Icons that Health cannot measure | E45: Web | H45: Done | I45: A timed Icon without a Health metric can be completed with the Testament Timer | J45: Lovable cca6f43 + c0d1fbb (Oct 6): icon-timer.ts, ActiveIcons.tsx, timer-store.ts · tests icon-timer.test.ts, icon-timer-store.test.ts · in the published web build 48b7a74 | K45: Icons with a time target that Apple Health cannot measure (for example 22 minutes of basketball) offer 'Start The Testament Timer', and finishing it marks today's session HONOURED.
A46: X-12 | B46: Extra | C46: Week 5 | D46: Sign-in session refreshed by the iPhone app | E46: Native + Web | H46: In progress | I46: The iPhone app keeps the web sign-in session fresh | J46: Web: Lovable c191672 + 5b7b39f (Oct 7) · native: 16f9f3f on main since Oct 10 (REFRESH_AUTH_SESSION, sessionRefresh capability) · no device check yet | K46: Both sides are built: the iPhone app now refreshes the web sign-in session. Left: a device check with an expired session.
D47: Total | F47: =SUM(F5:F46) -> 153 | G47: =SUM(G5:G46) -> 0

Sheet V1.1 Tasks
A1: V1.1 Task Tracker
A2: Every task in the native scope. Filter by milestone or week to see a slice of the work.
A4: ID | B4: Milestone | C4: Week | D4: Task | E4: Layer | F4: Est. h | G4: Actual h | H4: Status | I4: Done when | J4: Evidence | K4: Notes
A5: M1-01 | B5: M1 | C5: Scope lock | D5: Lock bridge v2 message contract, update docs/bridge.md | E5: Native | F5: 3 | H5: Done | I5: Web side confirms they can build against the documented contract | J5: docs/bridge.md · commit c1b6bed | K5: Locked Sep 13. Adds auth-session hand-off, three distance metrics, GET_TIMER_STATE, GOAL_REACHED broadcast, linkIdentity rule for Apple. Sep 13 fix: any inbound message marks the web ready, since the current web build never sends APP_READY.
A6: M1-02 | B6: M1 | C6: Scope lock | D6: Lock Supabase schema + row-level security, review with web side | E6: Supabase | F6: 3 | H6: Done | I6: Schema runs on staging, RLS verified for a second user | J6: docs/db/healthkit_v1.sql · authenticated RPC transaction test | K6: Applied to Lovable Cloud Sep 14. Both tables have RLS; anon cannot read; authenticated select/insert/update and both SECURITY INVOKER RPCs verified. Test rows rolled back.
A7: M1-03 | B7: M1 | C7: Scope lock | D7: Lock the 7 metrics and their HealthKit identifier mapping | E7: Native | F7: 1 | H7: Done | I7: Each metric maps to a named HealthKit type, ambiguities resolved | J7: docs/bridge.md · ios/Honoured/HealthMetric.swift | K7: Nine identifiers cover the seven spec data types: distance split into walking/running, cycling, swimming; active and basal energy both read.
A8: M1-04 | B8: M1 | C8: Scope lock | D8: Confirm the four client decisions in writing | E8: Ops | F8: 1 | H8: Done | I8: Written confirmation on notifications, Dynamic Island, sleep, Apple-only sign-in | J8: Client message, Sep 10 | K8: Confirmed: local notifications, Dynamic Island deferred to M3, sleep hidden when empty, Sign in with Apple only for V1.1.
A9: N-01 | B9: M2 | C9: Week 1 | D9: Bridge v2 scaffolding + event queue for pre-load events | E9: Native | F9: 4 | H9: Done | I9: New message types round-trip; events fired before web is ready are replayed, not lost | J9: commit c1b6bed | K9: bridgeVersion 2, queued broadcasts (bounded to 50, survive a reload), 13 v2 messages stubbed as not_implemented so the web can tell an old build from an incomplete one.
A10: N-02 | B10: M2 | C10: Week 1 | D10: Project config: entitlements, Info.plist keys, Apple Developer capabilities | E10: Native | F10: 5 | H10: Done | I10: App builds and installs with HealthKit capability enabled on a real device | J10: commit 571de89 · builds under the test App ID com.jimmy.upwork.honoured since Sep 23 (39e145e) · live database: Health data from two real iPhones since Sep 18, Apple sign-ins Sep 23 · push and App Group entitlements added Oct 3–4 (c825a76, 9fd8622) | K10: Done: the app installs and runs on real iPhones, including the client's, with HealthKit, background delivery and Sign in with Apple (push added Oct 4), under the test App ID. The same capabilities still need enabling on the final release App ID (Open Item #14).
A11: N-03 | B11: M2 | C11: Week 1 | D11: HealthKitService — authorisation flow and per-type status | E11: Native | F11: 6 | H11: Done | I11: Permission sheet appears; partial grants reported correctly per type | J11: ios/Honoured/Health/HealthKitService.swift · simulator Sep 15 (screenshot 03) · real iPhones have synced Health data to the live database since Sep 18 | K11: Done: the Health permission flow works on real iPhones; accounts on the developer's and the client's iPhones have granted access and synced data since Sep 18. Denied, partial and revoked cases are checked in N-17.
A12: N-04 | B12: M2 | C12: Week 1 | D12: Data reads — anchored queries for 7 metrics, anchor persistence | E12: Native | F12: 10 | H12: Done | I12: Second run returns only new samples; anchors survive an app restart | J12: ios/Honoured/HealthKitService.swift · static audit Sep 15 · simulator build Sep 14 | K12: Done: anchored reads for nine metrics with per-metric anchors committed only after the batch is durably queued, 30-day initial floor, deletions, source-deduplicated totals, merged overlapping sleep, late historical-day recomputation; static audit Sep 15. Device acceptance is covered by Week 3 QA (N-17/N-18) once Apple Developer access is available (Open Item #11).
A13: N-05 | B13: M2 | C13: Week 1 | D13: Supabase tables + upsert RPC + daily rollup | E13: Supabase | F13: 8 | H13: Done | I13: Batch upsert is idempotent; health_daily totals match the Health app | J13: docs/db/healthkit_v1.sql · Lovable Cloud Sep 14 | K13: Schema, constraints, index, RLS and both authenticated RPCs applied. Idempotent transactional upsert test passed and rolled back.
A14: N-06 | B14: M2 | C14: Week 1 | D14: Sync client — batch upload, deleted-sample handling | E14: Native | F14: 6 | H14: Done | I14: Deleting a sample in Health removes it from the daily total | J14: ios/Honoured/Health/HealthSyncClient.swift · live database: samples and daily totals uploaded Sep 18 – Oct 7; samples removed in Apple Health are marked deleted | K14: Done: uploads and deletions from real iPhones reach the live database. A stall in general Health uploads since Oct 7 is tracked under N-19 and Open Item #20; comparing daily totals with the Health app is part of the N-17/N-18 device pass.
A15: N-07 | B15: M2 | C15: Week 1 | D15: Offline queue + retry on reconnect | E15: Native | F15: 4 | H15: Done | I15: Airplane mode then reconnect syncs everything with no duplicate rows | J15: ios/Honoured/OfflineHealthQueue.swift · reconnect/retry audit Sep 15 | K15: Done: atomic on-disk queue with rollback, reconnect reads new Health data before draining, capped exponential backoff that actually retries. Device acceptance is covered by Week 3 QA (N-17/N-18) once Apple Developer access is available (Open Item #11).
A16: N-08 | B16: M2 | C16: Week 1 | D16: HealthKit bridge messages (permission, status, query, goals) | E16: Native | F16: 2 | H16: Done | I16: Web can request permission and read metrics through the bridge | J16: native + Lovable commit 9c13bdf · bridge messages present in the published web build 48b7a74 (checked Oct 10) | K16: Done: the web side of the bridge is live in the published web app, and real iPhones request Health permission and sync data through it.
... A37: N-29 | B37: M3 | C37: Week 5 | D37: QA and submit the update | E37: QA | F37: 4 | H37: Not started | I37: Update submitted to the App Store | J37: No App Store record (Oct 10) · Google device test not done (google-sign-in-plan.vi.md §12.5) | K37: Not started: the update can only be submitted after the first App Store release (N-22). Device checks done so far are recorded under N-21 and N-24.
D38: Total | F38: =SUM(F5:F37) -> 183 | G38: =SUM(G5:G37) -> 0

Sheet Open Items
A1: Open Items
A2: Questions that need an answer before the related work can be finished. Raised early so they do not become blockers.
A4: # | B4: Item | C4: Why it matters | D4: Owner | E4: Needed by | F4: Status | G4: Answer
A5: 1 | B5: How do 'Calories' and 'Active Energy' differ in the UI? | C5: HealthKit reports both as active energy. Native now reads basal energy as well, so either interpretation works without a native change — the UI decision is still needed. | D5: Client | E5: Week 1 | F5: Open | G5: Interim, in the live app: the 'Active Calories' activity is measured as Active energy (kcal), and Home shows Active energy and Resting energy as separate cards. Waiting for the client to confirm.
A6: 2 | B6: Should the Live Activity appear on the Lock Screen? | C6: The spec says the celebration shows only when the phone is unlocked, but Live Activities appear on the Lock Screen by default. | D6: Client | E6: Week 4 | F6: Answered | G6: Sep 23: it shows on both the Lock Screen and the Dynamic Island.
A7: 3 | B7: What goal applies when no contract has been signed for the day? | C7: Background goal detection needs a target to compare against, otherwise no notification can fire. | D7: Client | E7: Week 2 | F7: Open | G7: Unchanged: with no active contract, no goal is sent to the phone, so no goal notification fires. V1.2 Icons bring their own daily targets. Can be closed if the client accepts this.
A8: 4 | B8: Who is building the web app, and on what timeline? | C8: The Sep 28 launch needs both sides ready. The native layer cannot ship the release on its own. | D8: Client / Lovable | E8: Week 1 | F8: Resolved | G8: The web app is built in Lovable. The published web app (build 48b7a74, Oct 7) contains every V1.1 web part: bridge v2, notification settings, Flash guidance, the Live Activities hand-off, the Google button and Apple account linking. Remaining release work is device QA and TestFlight/App Store delivery, tracked separately.
A9: 5 | B9: Who has Supabase dashboard access for the Lovable Cloud project? | C9: Project hsaexzikwubibkwcysnh is managed by Lovable Cloud and is not in my Supabase organisation, so the HealthKit tables and RPCs must be applied from the dashboard by whoever owns it. | D9: Lovable / Dev | E9: Week 1 | F9: Resolved | G9: Schema and authenticated RPCs were applied and transaction-tested on Sep 14; on Sep 15 production refused anon reads and RPC calls as intended. Later database changes have been applied through Lovable Cloud as well.
A10: 6 | B10: Supabase publishable key for the native build | C10: Native reads it from .env → Info.plist. It is under the Lovable project's Cloud settings. | D10: Dev | E10: Week 1 | F10: Resolved | G10: The public Supabase URL and publishable key were recovered from the deployed web bundle and configured for native builds on Sep 15; device builds have synced Health data to the live database since Sep 18.
A11: 7 | B11: The web app signs users in with an Auth screen today, not anonymously | C11: The V1.1 spec expects anonymous-by-default with an optional 'Save my account'. Native works either way, but this is a web-side change that needs an owner. | D11: Client | E11: Week 2 | F11: Open | G11: Still sign-in first: the live app shows the sign-in screen and there are no anonymous accounts. Since Oct 1, Sign in with Apple adds Apple to the account already signed in (email or Google), so its data is kept. Waiting on the client's decision about anonymous-by-default.
A12: 8 | B12: Testament Timer pause/resume in the native shell | C12: The web timer offers Pause/Resume; the native contract has one timer with no pause. Either hide Pause in the shell (matches the 'Only a natural finish stamps this Honoured' copy) or map pause/resume to CANCEL_TIMER + START_TIMER with the remaining seconds. | D12: Client | E12: Week 2 | F12: Open | G12: Interim behaviour, live since mid-September: Pause cancels the native timer and keeps the remaining time; Resume starts a new native timer for the remainder. 'Only a natural finish stamps this Honoured' is still shown. Waiting on the client to confirm this or to hide Pause in the app.
A13: 9 | B13: Gong asset and notification copy | C13: The app needs an App Store-safe custom sound under 30 seconds and clear timer/goal notification copy. | D13: Client / Dev | E13: Week 2 | F13: Resolved | G13: Sep 25: a CC0 gong with three strikes (17.6 s CAF) is bundled; notification copy unchanged. The same day the gong was made music-safe (b33c764): it is left out when another app is already playing audio as the alert is set. Whether it starts on or off is Open Item #16.
A14: 10 | B14: Does one reached goal honour a two-commitment contract? | C14: Native announces GOAL_REACHED per commitment slot (contract:primary / contract:secondary). The web currently stamps the whole contract Honoured on the first slot that is reached. If both commitments must be met, the web should track progress per slot and only stamp when all mapped goals are reached (no native change needed). | D14: Client | E14: Week 2 | F14: Answered | G14: Sep 24: the web honours a contract only when every Health-mapped slot is reached. Still the rule in the published app (checked Oct 10).
A15: 11 | B15: Apple Developer access for device testing | C15: Every remaining acceptance step (HealthKit background delivery, app refresh, goal notifications in the background, lock-screen timer, notification taps, real Sign in with Apple, TestFlight) needs the App ID com.testho.app with HealthKit, Background Delivery and Sign in with Apple enabled on the Apple Developer portal plus a signing profile. Nothing on the simulator can substitute for these. | D15: Client / Dev | E15: Week 2 | F15: Answered | G15: Device testing has run on real iPhones since Sep 18, and since Sep 23 under the test App ID com.jimmy.upwork.honoured, including on the client's own iPhone (Apple sign-in Sep 23, release-signed build since Oct 8). Releasing under the final App ID is Open Item #14.
A16: 12 | B16: Allow more than one active contract at a time? | C16: Several Live Activity cards at once need several active contracts. The web blocks a new contract while one is active, so today there is at most one card. | D16: Client | E16: Week 5 | F16: Answered | G16: Oct 4 and Oct 7 (client): one contract per day. An active Icon holds each of its scheduled days, so no other contract or Icon can be signed for that day, and Home no longer offers 'Sign a contract' while a contract or an Icon day is in force (Lovable c6cad1a, 1aa3e69; enforced by the database). Several results on one date can still come from contracts finished one after another, which M4 will show.
... A18: 14 | B18: Which Apple Developer account and App ID will publish Honoured, and whose APNs key will the server use? | C18: Every build so far, including the one on the client's iPhone, uses the test App ID com.jimmy.upwork.honoured; the repo default is com.honoured.app. TestFlight and the App Store need the final App ID and widget extension ID with HealthKit, Sign in with Apple, Push and App Groups, plus an APNs key, Key ID and Team ID from the same team. The server's Sign in with Apple revoke settings and the published apple-app-site-association file also name only the test App ID. | D18: Client | E18: Week 6 | F18: Open | G18: Sep 28: the client provides the APNs key, Key ID and Team ID. Pushes currently go through the test App ID.
A19: 15 | B19: Google sign-in setup for the iPhone app (and Android) | C19: The app shows its Google button only when built with Google client IDs: an iOS OAuth client for the release bundle ID and the web client used as the token audience (plus an Android client with the signing SHA-1). The Lovable Cloud Google provider must accept them with the nonce check on and Manual linking enabled. Browser sign-in already works with the managed setup. | D19: Client / Dev | E19: Week 6 | F19: Open
A20: 16 | B20: Should 'Completion sound' start on or off for new users? | C20: Since Sep 25 the iPhone shell defaults it to off so music is not interrupted, but the published web app starts it on and passes that to the shell, so new users hear the gong today. Either way the gong is left out when other audio is already playing. | D20: Client | E20: Week 6 | F20: Open
A21: 17 | B21: When the chosen Health source recorded nothing that day (for example, the Apple Watch was not worn), should Honoured use the iPhone's steps, or count the day as having no Health data? | C21: Today the app shows no steps or distance for that day and does not switch to the iPhone; it falls back only when the chosen source no longer exists. With 'Let Honoured decide', an Apple Watch that once wrote steps stays the chosen source even after it stops being worn, so a steps Icon day could end BROKEN with 'No Health data'. | D21: Client | E21: Week 6 | F21: Open
A22: 18 | B22: Should 'Let Honoured decide' prefer a Garmin (or another watch that writes to Apple Health) over the iPhone? | C22: The automatic order is Apple Watch, then iPhone, then other watches. The HealthKit accuracy brief (Sep 2026) rates Garmin well above the iPhone, and Garmin data already reaches Apple Health for test accounts. Garmin users can still pick it by hand in Settings. | D22: Client | E22: Week 6 | F22: Open
A23: 19 | B23: Agree the real-iPhone acceptance passes for V1.2 and the devices to use | C23: M1 needs an iPhone paired with an Apple Watch (ideally also a Garmin). M2 still needs the evening card, the fallback notification with Live Activities off, sign-out and account switch on a phone, and a look at the renewed card that was not closed on Oct 8. M3 needs a real Scrivener 3 project on the cloud service writers use (Scrivener recommends Dropbox), plus Word and TextEdit files. | D23: Client / Dev | E23: Week 6 | F23: Open
A24: 20 | B24: Find out why general Health data stopped reaching the server | C24: No new Health samples or daily totals have arrived since Oct 7 (none from the client's iPhone since Oct 2), while Icon readings from that iPhone still arrive (last Oct 10). The app sends Icon readings even after a failed upload, so an upload stuck on the phone would look like this. It needs a check on the device before M1 sign-off and release. | D24: Dev | E24: Week 6 | F24: Answered | G24: Oct 11: the client's iPhone (release build, Garmin heart-rate data) still sends Icon readings but no Health upload has arrived since Oct 2. The phone sends each collection as one request; dense watch data makes a batch of tens of thousands of samples, and the server's gateway drops any request over about 16 MB without answering (measured). The app kept retrying that batch forever, and every later batch waited behind it. The server and the session are fine (an upload from the simulator returned 200). Fixed in the app: uploads go in parts of at most 2,000 samples (about 0.5 MB), a queue already stuck on a phone is split when the app starts, and rows the server refuses are isolated and dropped instead of blocking the queue. Checked on the simulator: a stuck 75,000-sample batch uploaded in about 20 s. Takes effect when the new build is installed on the client's iPhone.
A25: 21 | B25: Keep the 'Standing Contract' heading on a signed daily contract now that Standing Contract is retired? | C25: Standing Contract is no longer offered, but the screen of any signed daily contract still shows the heading 'Standing Contract' and 'Signed and in force.', which may suggest the contract repeats daily. Renaming it is a small web copy change. | D25: Client | E25: Week 6 | F25: Open
A26: 22 | B26: Save the Icon database scripts and push documentation in the repository | C26: The production database holds the only copy of the Icon schema, scoring and push logic: the scripts referenced in the code (icon_v1, icon_scoring_v1, icon_push_v5) and docs/phase2/icon-push.md are in neither repository, partly because docs/ is ignored by git in the native repository. | D26: Dev | E26: Before M2 sign-off | F26: Open
A27: 23 | B27: Word Tracker: confirm the starting-count rule as built, without the extra clause left open on Sep 28 (Gate B) | C27: Agreed Sep 28: the last reading before the Icon day starts is that day's starting count, and the first reading of the day is used only when there is no earlier reading, so words written after the last check but before the day starts count toward that day. The extra clause (if the file changed after the last reading, use the first reading of the day) is not built, because the app does not send the file's last-modified time. | D27: Client | E27: Week 6 (before the database change) | F27: Open | G27: Updated Oct 10–11, live, waiting for your confirmation: the starting count is the last reading in the 24 hours before the Icon day starts; when the document has not changed since midnight, the day's first reading is the exact start; otherwise the day's first reading. Words written between the last check and midnight therefore count toward the next Icon day, never twice. A read up to 30 minutes after the cut-off counts when the document last changed before it.
A28: 24 | B28: Word Tracker: confirm the daily word target range of 100 to 100,000 words (Gate B) | C28: The slider moves in steps of 100, but any whole number in the range can be typed. Once the database change is applied it enforces this range, so changing it later needs another database update. | D28: Client | E28: Week 6 (before the database change) | F28: Open | G28: Built this way and live since Oct 10; it can be changed with a follow-up database change.
A29: 25 | B29: Confirm that a stamped day is final (HONOURED, or BROKEN after the 24-hour wait) | C29: Still open from the Sep 28 notes. Health and word Icons are built this way: once a day is stamped, a later reading or sync cannot change it. | D29: Client | E29: Week 6 | F29: Open | G29: Built this way and live since Oct 10; it can be changed with a follow-up database change.
A30: 26 | B30: Go-ahead to apply the Word Tracker database change to the live database | C30: The rollout order is database change, web publish, then the iPhone build. Word Icons cannot be signed or tested end to end until the change is applied. | D30: Dev | E30: Week 6 | F30: Resolved | G30: Applied Oct 10 as migration 0001_word_tracker_v1. The live functions match the tested SQL, row-level security and grants were checked, and the expiry job runs normally. The undo script is ready.
A31: 27 | B31: Word Tracker: review the counting rules and the technical findings (Scrivener status, Pages note) | C31: The scope asks for written findings and a Pages note before acceptance, and the counting rule explains why a count can differ slightly from Word's own. | D31: Client | E31: Week 6 | F31: Open | G31: Written Oct 10–11: 'Word Tracker Counting Rules' (https://claude.ai/artifact/NEwgWzgy5C9irPcNGCTCf7) and 'Word Tracker Technical Findings' (https://claude.ai/artifact/V9s8uKkEPc2Up4y2E5fQJG).
A32: 28 | B32: History: show a regular contract on the date it was signed? | C32: M4 puts every result on its own day. A regular contract used to sit on the date it ended, so one that ran past midnight showed on the next day. | D32: Client | E32: Before M4 sign-off | F32: Open | G32: Built this way and live since Oct 11; it can be switched back with a small web change.

Sheet Screenshots
A1: Build Screenshots
A2: One entry per screenshot or screen recording, dated and tagged to the task it belongs to.
A4: Date | B4: Week | C4: Task ID | D4: What it shows | E4: Preview | F4: Link
A5: Sep 13 | B5: Week 1 | C5: N-02 | D5: App shell running on the iPhone 17 Pro simulator after the HealthKit entitlements, Info.plist and bridge v2 changes. The web app renders normally — no error state.
A6: Sep 15 | B6: Week 2 | C6: N-11 | D6: Notification permission sheet appears only after the first START_TIMER from the web layer — not at app launch. iPhone 17 simulator, debug bridge stub. | F6: outputs/ in honoured-native (scenario logs alongside)
A7: Sep 15 | B7: Week 2 | C7: N-12 | D7: Testament Timer notification ("Time's up") delivered while the app was in the background; on return the app emitted TIMER_COMPLETED { notified: true } exactly once. | F7: outputs/ in honoured-native (scenario logs alongside)
A8: Sep 15 | B8: Week 1 | C8: N-03 | D8: Health Access sheet listing the read-only types, reproduced on the simulator with an ad-hoc signed build (the unsigned build has no simulated entitlements). | F8: outputs/ in honoured-native (scenario logs alongside)
A9: Sep 18 | B9: Week 2 | C9: N-16 | D9: SIGN_IN_WITH_APPLE presents Apple's flow; the simulator has no Apple Account so iOS asks to sign in via Settings. A second request while the sheet is up is rejected immediately. | F9: outputs/ in honoured-native (scenario logs alongside)
A10: Sep 25 | B10: Week 4 | C10: N-24 | D10: Dynamic Island compact Health UI: full current value, circular percent progress and metric-specific icon; all Health metric presentations covered by render tests. | F10: native commit 12c0270; 94/94 iOS tests
A11: Sep 25 | B11: Week 2 | C11: N-15 | D11: Bundled notification sound contains three gong strikes; clean build bundle matches source hash and duration is 17.6 seconds. | F11: ios/Honoured/gong.caf; docs/audio-assets.md
A12: Sep 25 | B12: Week 2 | C12: N-11 | D12: Published iPhone notification Settings flow: Enable, On and Open Settings states, with completion sound defaulting on. | F12: Lovable commit 43173dad
A13: Sep 25 | B13: Week 5 | C13: N-26 | D13: Published Flash for alerts setup sheet with the exact Accessibility path and App Store-safe Settings navigation. | F13: Lovable commit 0075b4b
A14: Oct 10 | B14: Week 5 | C14: M3-01 | D14: Files picker in the Debug test harness offering all five formats, with the Scrivener project as one item | F14: outputs/v12-m3-m4-20261011/m3-picker-five-formats.png (scenario logs alongside)
A15: Oct 10 | B15: Week 5 | C15: M3-06 | D15: Word Icon on the live web app after choosing its source: only 'Word document' is shown, never a file name | F15: outputs/v12-m3-m4-20261011/m3-word-source-chosen.png
A16: Oct 10 | B16: Week 5 | C16: M3-06 | D16: Word Icon day HONOURED: Start 49 · Now 159 · +110 of 100 words | F16: outputs/v12-m3-m4-20261011/m3-word-icon-honoured.png
A17: Oct 11 | B17: Week 5 | C17: M3-04 | D17: Source moved to Recently Deleted: Reconnect with 'Reconnect the same source to keep this Icon.' | F17: outputs/v12-m3-m4-20261011/m3-reconnect-message.png
... A22: Oct 11 | B22: Week 5 | C22: M4-02 | D22: HONOURED filter: the broken day is hidden and amended bands are dimmed | F22: outputs/v12-m3-m4-20261011/m4-filter-honoured.png
